Workbook

Sheet 📋 Sommaire
A1: 🌸 SakuraLeveling V2 — Contenu du jeu
A2: Généré le 2026-10-25 16:07 UTC
A4: Feuille | B4: Contenu
A5: 🎽 Équipements | B5: Les 23 pièces (stats du COMMUN), le monstre qui la porte et son passif. Power calculé au niveau 30.
A6: 👹 Mobs | B6: Monstres : stats, drops, Power & Rang calculés en direct.
A7: 🧪 Consommables / 📦 Ressources | B7: Potions et ressources de craft.
A8: 🏪 Shop | B8: Prix d'achat / vente du shop.
A9: 🌳 Skill Tree | B9: Tous les nœuds de l'arbre.
A10: 🏷️ Titres | B10: Titres, conditions et effets.
A11: 🐉 World Bosses | B11: Bosses + modifiers.
A12: ⚙️ Calibrage | B12: Constantes du score de puissance. NE PAS supprimer.
A14: 🛠️ Comment équilibrer (round-trip)
A15: 1. Filtre : clique la flèche d'un en-tête (ex : colonne Type = « Casque », ou Panoplie = « gobelin »).
A16: 2. Édite les colonnes de stats (Atk, Def, PV, Crit %, Crit dmg, Esquive, Vitesse, Regen), le Prix, la Rareté, le Slot, la Panoplie, le Nom…
A17: 3. La colonne « Power » (fond gris) est AUTO-CALCULÉE — ne l'édite pas, elle se met à jour toute seule quand tu changes une stat.
A18: 4. Tu peux AJOUTER une ligne d'équipement : remplis au moins Code + Type. Tu peux en supprimer aussi.
A19: 5. Renvoie-moi le fichier .xlsx modifié → je réapplique via scripts/import_content_spreadsheet.py (puis seed + déploiement).
A21: Conventions stats : crit_chance & esquive en 0..100 ; crit_damage 100 = neutre, 150 = ×1,5 ; défense soustractive (1 DEF ≈ 25 PV effectifs).
A22: Power d'un équipement = puissance MARGINALE qu'il ajoute à un perso de base (power(base+item) − power(base)).

Sheet 🎽 Équipements
A1: Code | B1: Nom | C1: Type | D1: Slot | E1: Porté par | F1: Passif (dès épique) | G1: Panoplie | H1: 2-mains | I1: Atk % | J1: Def % | K1: PV % | L1: Crit % | M1: Crit dmg | N1: Esquive | O1: Vitesse | P1: Regen | Q1: Mana max | R1: Regen mana | S1: Power | T1: Description
A2: baton_du_crane_totem | B2: Bâton du crâne-totem | C2: Arme | D2: arme | E2: Gobelin Chaman | F2: Mains guérisseuses — Tes soins donnés sont augmentés de 10 %, et 10 % des soins que tu donnes à un allié frappent aussi l'ennemi. | H2: non | I2: 8 | J2: 0 | K2: 0 | L2: 0 | M2: 0 | N2: 0 | O2: 0 | P2: 0 | Q2: 15 | R2: 0 | S2: 60 | T2: Le crâne au sommet murmure encore des incantations.
A3: fendoir_d_orage | B3: Fendoir d'orage | C3: Arme | D3: arme | E3: Ogre démoniaque | F3: Tueur de boss — +15 % de dégâts contre les boss. | H3: non | I3: 8 | J3: 0 | K3: 0 | L3: 0 | M3: 0 | N3: 0 | O3: 1 | P3: 0 | Q3: 0 | R3: 0 | S3: 69 | T3: La foudre court le long du tranchant.
A4: griffes_de_goule | B4: Griffes de goule | C4: Arme | D4: arme | E4: Goule | F4: — | H4: non | I4: 8 | J4: 0 | K4: 0 | L4: 2 | M4: 0 | N4: 0 | O4: 0 | P4: 0 | Q4: 0 | R4: 0 | S4: 69 | T4: Des griffes jaunies montées sur un gantelet.
A5: lance_des_kobolds | B5: Lance des kobolds | C5: Arme | D5: arme | E5: Kobold | F5: — | H5: oui | I5: 20 | J5: 0 | K5: 0 | L5: 0 | M5: 0 | N5: 0 | O5: -1 | P5: 0 | Q5: 0 | R5: 0 | S5: 141 | T5: Une longue lance à crochets, faite pour tenir les dragons à distance.
A6: massue_du_chef_de_guerre | B6: Massue du chef de guerre | C6: Arme | D6: arme | E6: Gobelin Supérieur | F6: Fureur montante — Chaque attaque augmente ton attaque de 1 % pour le combat (max +20 %). | H6: non | I6: 8 | J6: 0 | K6: 0 | L6: 0 | M6: 8 | N6: 0 | O6: 0 | P6: 0 | Q6: 0 | R6: 0 | S6: 64 | T6: Chaque pointe porte le nom d'un ennemi tombé.
A7: rapiere_ecarlate | B7: Rapière écarlate | C7: Arme | D7: arme | E7: Vampire noble | F7: — | H7: non | I7: 8 | J7: 0 | K7: 0 | L7: 0 | M7: 6 | N7: 0 | O7: 0 | P7: 0 | Q7: 0 | R7: 0 | S7: 63 | T7: Fine, rapide, et toujours rouge.
A8: surin_dentele | B8: Surin dentelé | C8: Arme | D8: arme | E8: Gobelin | F8: Frappe d'ouverture — Ta première attaque est forcément critique ; si elle l'était déjà, c'est un super-critique (les deux critiques se cumulent). | H8: non | I8: 8 | J8: 0 | K8: 0 | L8: 3 | M8: 0 | N8: 0 | O8: 0 | P8: 0 | Q8: 0 | R8: 0 | S8: 74 | T8: Une lame courbe ébréchée, plus rapide que la pensée d'un gobelin.
A9: trident_ricaneur | B9: Trident ricaneur | C9: Arme | D9: arme | E9: Diablotin | F9: Coup double — 10 % de chance d'attaquer deux fois d'affilée. | H9: non | I9: 8 | J9: 0 | K9: 0 | L9: 0 | M9: 6 | N9: 0 | O9: 0 | P9: 0 | Q9: 0 | R9: 0 | S9: 63 | T9: On jurerait l'entendre rire à chaque coup.
A10: tronc_arrache | B10: Tronc arraché | C10: Arme | D10: arme | E10: Gobelin Géant | F10: Exécuteur — +20 % de dégâts contre un ennemi sous 50 % de ses PV. | H10: oui | I10: 20 | J10: 0 | K10: 0 | L10: 0 | M10: 0 | N10: 0 | O10: -1 | P10: 0 | Q10: 0 | R10: 0 | S10: 141 | T10: Un arbre entier, déraciné à mains nues.
A11: epee_de_l_ossuaire | B11: Épée de l'ossuaire | C11: Arme | D11: arme | E11: Squelette | F11: Perce-armure — Tes coups ignorent 15 % de la défense ennemie. | H11: non | I11: 8 | J11: 0 | K11: 0 | L11: 2 | M11: 0 | N11: 0 | O11: 0 | P11: 0 | Q11: 0 | R11: 0 | S11: 69 | T11: Rouillée, mais elle trouve toujours le défaut de l'armure.
A12: pavois_de_granit | B12: Pavois de granit | C12: Bouclier | D12: arme | E12: Gargouille | F12: Peau de pierre — Chaque coup subi augmente ta défense de 1 % pour le combat (max +20 %). | H12: non | I12: 0 | J12: 6 | K12: 4 | L12: 0 | M12: 0 | N12: 0 | O12: 0 | P12: 0 | Q12: 0 | R12: 0 | S12: 35 | T12: Plus on le frappe, plus il se durcit.
A13: ecu_de_l_eclipse | B13: Écu de l'éclipse | C13: Bouclier | D13: arme | E13: Chevalier de l'éclipse | F13: — | H13: non | I13: 0 | J13: 6 | K13: 4 | L13: 0 | M13: 0 | N13: 0 | O13: 0 | P13: 0 | Q13: 0 | R13: 0 | S13: 35 | T13: Un bouclier où le soleil ne se reflète plus.
... A51: oeil_de_verre_noir | B51: Œil de verre noir | C51: Accessoire | D51: accessoire | E51: Œil errant | F51: — | H51: non | I51: 0 | J51: 0 | K51: 0 | L51: 3 | M51: 0 | N51: 0 | O51: 0 | P51: 0 | Q51: 0 | R51: 0 | S51: 12 | T51: On y voit les points faibles de ses ennemis.

Sheet 👹 Mobs
A1: Code | B1: Nom | C1: Famille | D1: PV max | E1: Atk | F1: Def | G1: Vit | H1: Crit % | I1: Crit dmg | J1: Esquive | K1: Regen | L1: XP récomp. | M1: Or récomp. | N1: Poids spawn | O1: Power | P1: Rang | Q1: Drops | R1: Image | S1: Description
A2: slime | B2: Slime | C2: slime | D2: 110 | E2: 8 | F2: 4 | G2: 5 | H2: 0 | I2: 100 | J2: 0 | K2: 0 | L2: 6 | M2: 3 | N2: 40 | O2: =ROUND((E2*(1+(H2/100)*MAX(0,I2-100)/100)*(1+G2/100))*((D2+F2*'⚙️ Calibrage'!$B$9)/MAX(0.01,1-J2/100))/'⚙️ Calibrage'!$B$10,0) | P2: =IFERROR(VLOOKUP(O2,'⚙️ Calibrage'!$D$2:$E$29,2,TRUE),"?") | Q2: potion_soin ×1-1 (10%) | R2: slime.png | S2: Une créature gélatineuse faible.
A3: gobelin | B3: Gobelin | C3: gobelin | D3: 154 | E3: 14 | F3: 6 | G3: 5 | H3: 0 | I3: 100 | J3: 0 | K3: 0 | L3: 38 | M3: 18 | N3: 40 | O3: =ROUND((E3*(1+(H3/100)*MAX(0,I3-100)/100)*(1+G3/100))*((D3+F3*'⚙️ Calibrage'!$B$9)/MAX(0.01,1-J3/100))/'⚙️ Calibrage'!$B$10,0) | P3: =IFERROR(VLOOKUP(O3,'⚙️ Calibrage'!$D$2:$E$29,2,TRUE),"?") | R3: gobelin.png | S3: Une créature faible.
A4: gobelin_combattant | B4: Gobelin Combattant | C4: gobelin | D4: 198 | E4: 21 | F4: 8 | G4: 5 | H4: 0 | I4: 100 | J4: 0 | K4: 0 | L4: 62 | M4: 30 | N4: 30 | O4: =ROUND((E4*(1+(H4/100)*MAX(0,I4-100)/100)*(1+G4/100))*((D4+F4*'⚙️ Calibrage'!$B$9)/MAX(0.01,1-J4/100))/'⚙️ Calibrage'!$B$10,0) | P4: =IFERROR(VLOOKUP(O4,'⚙️ Calibrage'!$D$2:$E$29,2,TRUE),"?") | R4: gobelin_combattant.png | S4: Une créature endurcie.
A5: squelette | B5: Squelette | C5: mort-vivant | D5: 231 | E5: 26 | F5: 9 | G5: 5 | H5: 0 | I5: 100 | J5: 0 | K5: 0 | L5: 88 | M5: 42 | N5: 25 | O5: =ROUND((E5*(1+(H5/100)*MAX(0,I5-100)/100)*(1+G5/100))*((D5+F5*'⚙️ Calibrage'!$B$9)/MAX(0.01,1-J5/100))/'⚙️ Calibrage'!$B$10,0) | P5: =IFERROR(VLOOKUP(O5,'⚙️ Calibrage'!$D$2:$E$29,2,TRUE),"?") | R5: squelette.png | S5: Un pantin d'os réanimé. Le premier pas dans le royaume des morts.
A6: gobelin_chaman | B6: Gobelin Chaman | C6: gobelin | D6: 194 | E6: 42 | F6: 5 | G6: 5 | H6: 0 | I6: 100 | J6: 0 | K6: 0 | L6: 94 | M6: 45 | N6: 30 | O6: =ROUND((E6*(1+(H6/100)*MAX(0,I6-100)/100)*(1+G6/100))*((D6+F6*'⚙️ Calibrage'!$B$9)/MAX(0.01,1-J6/100))/'⚙️ Calibrage'!$B$10,0) | P6: =IFERROR(VLOOKUP(O6,'⚙️ Calibrage'!$D$2:$E$29,2,TRUE),"?") | R6: gobelin_chaman.png | S6: Une créature intelligente.
A7: zombie | B7: Zombie | C7: mort-vivant | D7: 248 | E7: 23 | F7: 15 | G7: 5 | H7: 0 | I7: 100 | J7: 0 | K7: 0 | L7: 112 | M7: 54 | N7: 20 | O7: =ROUND((E7*(1+(H7/100)*MAX(0,I7-100)/100)*(1+G7/100))*((D7+F7*'⚙️ Calibrage'!$B$9)/MAX(0.01,1-J7/100))/'⚙️ Calibrage'!$B$10,0) | P7: =IFERROR(VLOOKUP(O7,'⚙️ Calibrage'!$D$2:$E$29,2,TRUE),"?") | R7: zombie.png | S7: Une carcasse putride et lente, mais coriace.
A8: gobelin_ballon | B8: Gobelin Ballon | C8: gobelin | D8: 286 | E8: 34 | F8: 12 | G8: 5 | H8: 0 | I8: 100 | J8: 0 | K8: 0 | L8: 119 | M8: 57 | N8: 20 | O8: =ROUND((E8*(1+(H8/100)*MAX(0,I8-100)/100)*(1+G8/100))*((D8+F8*'⚙️ Calibrage'!$B$9)/MAX(0.01,1-J8/100))/'⚙️ Calibrage'!$B$10,0) | P8: =IFERROR(VLOOKUP(O8,'⚙️ Calibrage'!$D$2:$E$29,2,TRUE),"?") | R8: gobelin_ballon.png | S8: Un groupe de créatures inventives.
A9: gobelin_geant | B9: Gobelin Géant | C9: gobelin | D9: 287 | E9: 28 | F9: 17 | G9: 6 | H9: 0 | I9: 100 | J9: 0 | K9: 0 | L9: 144 | M9: 69 | N9: 20 | O9: =ROUND((E9*(1+(H9/100)*MAX(0,I9-100)/100)*(1+G9/100))*((D9+F9*'⚙️ Calibrage'!$B$9)/MAX(0.01,1-J9/100))/'⚙️ Calibrage'!$B$10,0) | P9: =IFERROR(VLOOKUP(O9,'⚙️ Calibrage'!$D$2:$E$29,2,TRUE),"?") | R9: gobelin_geant.png | S9: Une créature imposante.
A10: momie | B10: Momie | C10: mort-vivant | D10: 330 | E10: 41 | F10: 14 | G10: 6 | H10: 0 | I10: 100 | J10: 0 | K10: 0 | L10: 150 | M10: 72 | N10: 10 | O10: =ROUND((E10*(1+(H10/100)*MAX(0,I10-100)/100)*(1+G10/100))*((D10+F10*'⚙️ Calibrage'!$B$9)/MAX(0.01,1-J10/100))/'⚙️ Calibrage'!$B$10,0) | P10: =IFERROR(VLOOKUP(O10,'⚙️ Calibrage'!$D$2:$E$29,2,TRUE),"?") | R10: momie.png | S10: Un corps embaumé aux bandelettes maudites, quasi increvable.
A11: gobelin_runique | B11: Gobelin Runique | C11: gobelin | D11: 290 | E11: 69 | F11: 7 | G11: 6 | H11: 0 | I11: 100 | J11: 0 | K11: 0 | L11: 169 | M11: 81 | N11: 20 | O11: =ROUND((E11*(1+(H11/100)*MAX(0,I11-100)/100)*(1+G11/100))*((D11+F11*'⚙️ Calibrage'!$B$9)/MAX(0.01,1-J11/100))/'⚙️ Calibrage'!$B$10,0) | P11: =IFERROR(VLOOKUP(O11,'⚙️ Calibrage'!$D$2:$E$29,2,TRUE),"?") | R11: gobelin_runique.png | S11: Une créature mystérieuse.
A12: fantome | B12: Fantôme | C12: mort-vivant | D12: 231 | E12: 46 | F12: 13 | G12: 11 | H12: 20 | I12: 150 | J12: 0 | K12: 0 | L12: 188 | M12: 90 | N12: 15 | O12: =ROUND((E12*(1+(H12/100)*MAX(0,I12-100)/100)*(1+G12/100))*((D12+F12*'⚙️ Calibrage'!$B$9)/MAX(0.01,1-J12/100))/'⚙️ Calibrage'!$B$10,0) | P12: =IFERROR(VLOOKUP(O12,'⚙️ Calibrage'!$D$2:$E$29,2,TRUE),"?") | R12: fantome.png | S12: Une âme errante insaisissable qui glisse entre les coups.
A13: gobelin_assassin | B13: Gobelin Assassin | C13: gobelin | D13: 238 | E13: 47 | F13: 13 | G13: 11 | H13: 20 | I13: 150 | J13: 0 | K13: 0 | L13: 194 | M13: 93 | N13: 10 | O13: =ROUND((E13*(1+(H13/100)*MAX(0,I13-100)/100)*(1+G13/100))*((D13+F13*'⚙️ Calibrage'!$B$9)/MAX(0.01,1-J13/100))/'⚙️ Calibrage'!$B$10,0) | P13: =IFERROR(VLOOKUP(O13,'⚙️ Calibrage'!$D$2:$E$29,2,TRUE),"?") | R13: gobelin_assassin.png | S13: Une créature discrète.
A14: gobelin_superieur | B14: Gobelin Supérieur | C14: gobelin | D14: 1320 | E14: 178 | F14: 18 | G14: 6 | H14: 0 | I14: 100 | J14: 0 | K14: 0 | L14: 656 | M14: 315 | N14: 10 | O14: =ROUND((E14*(1+(H14/100)*MAX(0,I14-100)/100)*(1+G14/100))*((D14+F14*'⚙️ Calibrage'!$B$9)/MAX(0.01,1-J14/100))/'⚙️ Calibrage'!$B$10,0) | P14: =IFERROR(VLOOKUP(O14,'⚙️ Calibrage'!$D$2:$E$29,2,TRUE),"?") | R14: gobelin_superieur.png | S14: Une créature supérieure.
... A17: banshee | B17: Banshee | C17: mort-vivant | D17: 440 | E17: 117 | F17: 11 | G17: 7 | H17: 0 | I17: 100 | J17: 0 | K17: 0 | L17: 281 | M17: 135 | N17: 2 | O17: =ROUND((E17*(1+(H17/100)*MAX(0,I17-100)/100)*(1+G17/100))*((D17+F17*'⚙️ Calibrage'!$B$9)/MAX(0.01,1-J17/100))/'⚙️ Calibrage'!$B$10,0) | P17: =IFERROR(VLOOKUP(O17,'⚙️ Calibrage'!$D$2:$E$29,2,TRUE),"?") | R17: banshee.png | S17: Un spectre hurlant dont le cri glaçant transperce l'âme.
A18: loup_sacre | B18: Loup sacré | C18: primordial | D18: 337 | E18: 72 | F18: 18 | G18: 13 | H18: 20 | I18: 150 | J18: 0 | K18: 0 | L18: 288 | M18: 138 | N18: 40 | O18: =ROUND((E18*(1+(H18/100)*MAX(0,I18-100)/100)*(1+G18/100))*((D18+F18*'⚙️ Calibrage'!$B$9)/MAX(0.01,1-J18/100))/'⚙️ Calibrage'!$B$10,0) | P18: =IFERROR(VLOOKUP(O18,'⚙️ Calibrage'!$D$2:$E$29,2,TRUE),"?") | S18: Gardien à la fourrure d'argent ; il chasse en meute depuis l'aube des temps.
A19: cerf_esprit | B19: Cerf-esprit | C19: primordial | D19: 583 | E19: 85 | F19: 24 | G19: 7 | H19: 0 | I19: 100 | J19: 0 | K19: 0 | L19: 300 | M19: 144 | N19: 30 | O19: =ROUND((E19*(1+(H19/100)*MAX(0,I19-100)/100)*(1+G19/100))*((D19+F19*'⚙️ Calibrage'!$B$9)/MAX(0.01,1-J19/100))/'⚙️ Calibrage'!$B$10,0) | P19: =IFERROR(VLOOKUP(O19,'⚙️ Calibrage'!$D$2:$E$29,2,TRUE),"?") | S19: Un cerf translucide ; la forêt se tait sur son passage.
A20: serpent_des_racines | B20: Serpent des racines | C20: primordial | D20: 363 | E20: 80 | F20: 20 | G20: 13 | H20: 20 | I20: 150 | J20: 0 | K20: 0 | L20: 312 | M20: 150 | N20: 25 | O20: =ROUND((E20*(1+(H20/100)*MAX(0,I20-100)/100)*(1+G20/100))*((D20+F20*'⚙️ Calibrage'!$B$9)/MAX(0.01,1-J20/100))/'⚙️ Calibrage'!$B$10,0) | P20: =IFERROR(VLOOKUP(O20,'⚙️ Calibrage'!$D$2:$E$29,2,TRUE),"?") | S20: Il dort sous les racines et frappe d'un venin sylvestre.
A21: demon_cornu | B21: Démon cornu | C21: demoniaque | D21: 638 | E21: 93 | F21: 26 | G21: 7 | H21: 0 | I21: 100 | J21: 0 | K21: 0 | L21: 325 | M21: 156 | N21: 30 | O21: =ROUND((E21*(1+(H21/100)*MAX(0,I21-100)/100)*(1+G21/100))*((D21+F21*'⚙️ Calibrage'!$B$9)/MAX(0.01,1-J21/100))/'⚙️ Calibrage'!$B$10,0) | P21: =IFERROR(VLOOKUP(O21,'⚙️ Calibrage'!$D$2:$E$29,2,TRUE),"?") | R21: demon_cornu.png | S21: Fantassin cornu des légions infernales, brutal et sans pitié.
A22: ours_colosse | B22: Ours colosse | C22: primordial | D22: 510 | E22: 140 | F22: 13 | G22: 7 | H22: 0 | I22: 100 | J22: 0 | K22: 0 | L22: 325 | M22: 156 | N22: 20 | O22: =ROUND((E22*(1+(H22/100)*MAX(0,I22-100)/100)*(1+G22/100))*((D22+F22*'⚙️ Calibrage'!$B$9)/MAX(0.01,1-J22/100))/'⚙️ Calibrage'!$B$10,0) | P22: =IFERROR(VLOOKUP(O22,'⚙️ Calibrage'!$D$2:$E$29,2,TRUE),"?") | S22: Ses griffes fendent la pierre comme l'armure.
A23: liche_maudite | B23: Liche maudite | C23: mort-vivant | D23: 9504 | E23: 146 | F23: 14 | G23: 7 | H23: 0 | I23: 100 | J23: 0 | K23: 0 | L23: 1012 | M23: 486 | N23: 4 | O23: =ROUND((E23*(1+(H23/100)*MAX(0,I23-100)/100)*(1+G23/100))*((D23+F23*'⚙️ Calibrage'!$B$9)/MAX(0.01,1-J23/100))/'⚙️ Calibrage'!$B$10,0) | P23: =IFERROR(VLOOKUP(O23,'⚙️ Calibrage'!$D$2:$E$29,2,TRUE),"?") | R23: liche_maudite.png | S23: Un sorcier mort-vivant dont la magie noire dévaste.
A24: golem_de_mousse | B24: Golem de mousse | C24: primordial | D24: 594 | E24: 68 | F24: 36 | G24: 7 | H24: 0 | I24: 100 | J24: 0 | K24: 0 | L24: 338 | M24: 162 | N24: 15 | O24: =ROUND((E24*(1+(H24/100)*MAX(0,I24-100)/100)*(1+G24/100))*((D24+F24*'⚙️ Calibrage'!$B$9)/MAX(0.01,1-J24/100))/'⚙️ Calibrage'!$B$10,0) | P24: =IFERROR(VLOOKUP(O24,'⚙️ Calibrage'!$D$2:$E$29,2,TRUE),"?") | S24: Un rocher couvert de mousse qui repousse plus vite qu'on ne l'arrache.
A25: aigle_tempete | B25: Aigle-tempête | C25: primordial | D25: 3274 | E25: 138 | F25: 22 | G25: 13 | H25: 20 | I25: 150 | J25: 0 | K25: 0 | L25: 1050 | M25: 504 | N25: 10 | O25: =ROUND((E25*(1+(H25/100)*MAX(0,I25-100)/100)*(1+G25/100))*((D25+F25*'⚙️ Calibrage'!$B$9)/MAX(0.01,1-J25/100))/'⚙️ Calibrage'!$B$10,0) | P25: =IFERROR(VLOOKUP(O25,'⚙️ Calibrage'!$D$2:$E$29,2,TRUE),"?") | S25: Chacun de ses battements d'ailes soulève une bourrasque.
A26: chauve_souris_geante | B26: Chauve-souris géante | C26: nocturne | D26: 416 | E26: 94 | F26: 23 | G26: 13 | H26: 20 | I26: 150 | J26: 0 | K26: 0 | L26: 356 | M26: 171 | N26: 40 | O26: =ROUND((E26*(1+(H26/100)*MAX(0,I26-100)/100)*(1+G26/100))*((D26+F26*'⚙️ Calibrage'!$B$9)/MAX(0.01,1-J26/100))/'⚙️ Calibrage'!$B$10,0) | P26: =IFERROR(VLOOKUP(O26,'⚙️ Calibrage'!$D$2:$E$29,2,TRUE),"?") | S26: Elle surgit de l'éclipse par nuées entières.
A27: goule | B27: Goule | C27: nocturne | D27: 715 | E27: 107 | F27: 29 | G27: 7 | H27: 0 | I27: 100 | J27: 0 | K27: 0 | L27: 362 | M27: 174 | N27: 30 | O27: =ROUND((E27*(1+(H27/100)*MAX(0,I27-100)/100)*(1+G27/100))*((D27+F27*'⚙️ Calibrage'!$B$9)/MAX(0.01,1-J27/100))/'⚙️ Calibrage'!$B$10,0) | P27: =IFERROR(VLOOKUP(O27,'⚙️ Calibrage'!$D$2:$E$29,2,TRUE),"?") | S27: Elle rôde entre les tombes, affamée de chair fraîche.
A28: loup_garou | B28: Loup-garou | C28: nocturne | D28: 590 | E28: 168 | F28: 15 | G28: 8 | H28: 0 | I28: 100 | J28: 0 | K28: 0 | L28: 375 | M28: 180 | N28: 25 | O28: =ROUND((E28*(1+(H28/100)*MAX(0,I28-100)/100)*(1+G28/100))*((D28+F28*'⚙️ Calibrage'!$B$9)/MAX(0.01,1-J28/100))/'⚙️ Calibrage'!$B$10,0) | P28: =IFERROR(VLOOKUP(O28,'⚙️ Calibrage'!$D$2:$E$29,2,TRUE),"?") | S28: Sous l'éclipse, la bête l'emporte sur l'homme — et sa rage grandit avec ses blessures.
A29: ogre_demoniaque | B29: Ogre démoniaque | C29: demoniaque | D29: 607 | E29: 176 | F29: 16 | G29: 8 | H29: 0 | I29: 100 | J29: 0 | K29: 0 | L29: 388 | M29: 186 | N29: 20 | O29: =ROUND((E29*(1+(H29/100)*MAX(0,I29-100)/100)*(1+G29/100))*((D29+F29*'⚙️ Calibrage'!$B$9)/MAX(0.01,1-J29/100))/'⚙️ Calibrage'!$B$10,0) | P29: =IFERROR(VLOOKUP(O29,'⚙️ Calibrage'!$D$2:$E$29,2,TRUE),"?") | R29: ogre_demoniaque.png | S29: Masse de muscles corrompue qui écrase tout sur son passage.
A30: sorciere_de_sang | B30: Sorcière de sang | C30: nocturne | D30: 607 | E30: 176 | F30: 16 | G30: 8 | H30: 0 | I30: 100 | J30: 0 | K30: 0 | L30: 388 | M30: 186 | N30: 20 | O30: =ROUND((E30*(1+(H30/100)*MAX(0,I30-100)/100)*(1+G30/100))*((D30+F30*'⚙️ Calibrage'!$B$9)/MAX(0.01,1-J30/100))/'⚙️ Calibrage'!$B$10,0) | P30: =IFERROR(VLOOKUP(O30,'⚙️ Calibrage'!$D$2:$E$29,2,TRUE),"?") | S30: Elle appelle ses familiers d'un murmure.
A31: chevalier_de_l_eclipse | B31: Chevalier de l'éclipse | C31: nocturne | D31: 713 | E31: 86 | F31: 43 | G31: 8 | H31: 0 | I31: 100 | J31: 0 | K31: 0 | L31: 400 | M31: 192 | N31: 15 | O31: =ROUND((E31*(1+(H31/100)*MAX(0,I31-100)/100)*(1+G31/100))*((D31+F31*'⚙️ Calibrage'!$B$9)/MAX(0.01,1-J31/100))/'⚙️ Calibrage'!$B$10,0) | P31: =IFERROR(VLOOKUP(O31,'⚙️ Calibrage'!$D$2:$E$29,2,TRUE),"?") | S31: Son armure noire rend chaque coup à celui qui l'a porté.
A32: vampire_noble | B32: Vampire noble | C32: nocturne | D32: 814 | E32: 126 | F32: 33 | G32: 8 | H32: 0 | I32: 100 | J32: 0 | K32: 0 | L32: 412 | M32: 198 | N32: 10 | O32: =ROUND((E32*(1+(H32/100)*MAX(0,I32-100)/100)*(1+G32/100))*((D32+F32*'⚙️ Calibrage'!$B$9)/MAX(0.01,1-J32/100))/'⚙️ Calibrage'!$B$10,0) | P32: =IFERROR(VLOOKUP(O32,'⚙️ Calibrage'!$D$2:$E$29,2,TRUE),"?") | S32: Il boit la vie de ses adversaires avec élégance.
A33: comtesse_ecarlate | B33: Comtesse écarlate | C33: nocturne | D33: 8910 | E33: 344 | F33: 27 | G33: 14 | H33: 20 | I33: 150 | J33: 0 | K33: 0 | L33: 1256 | M33: 603 | N33: 5 | O33: =ROUND((E33*(1+(H33/100)*MAX(0,I33-100)/100)*(1+G33/100))*((D33+F33*'⚙️ Calibrage'!$B$9)/MAX(0.01,1-J33/100))/'⚙️ Calibrage'!$B$10,0) | P33: =IFERROR(VLOOKUP(O33,'⚙️ Calibrage'!$D$2:$E$29,2,TRUE),"?") | S33: Un regard, et ses ennemis se battent pour elle.
A34: kobold | B34: Kobold | C34: draconique | D34: 836 | E34: 129 | F34: 34 | G34: 8 | H34: 0 | I34: 100 | J34: 0 | K34: 0 | L34: 425 | M34: 204 | N34: 40 | O34: =ROUND((E34*(1+(H34/100)*MAX(0,I34-100)/100)*(1+G34/100))*((D34+F34*'⚙️ Calibrage'!$B$9)/MAX(0.01,1-J34/100))/'⚙️ Calibrage'!$B$10,0) | P34: =IFERROR(VLOOKUP(O34,'⚙️ Calibrage'!$D$2:$E$29,2,TRUE),"?") | S34: Petit, rusé, armé d'une lance trop grande pour lui.
A35: cerbere | B35: Cerbère | C35: demoniaque | D35: 858 | E35: 133 | F35: 35 | G35: 8 | H35: 0 | I35: 100 | J35: 0 | K35: 0 | L35: 438 | M35: 210 | N35: 15 | O35: =ROUND((E35*(1+(H35/100)*MAX(0,I35-100)/100)*(1+G35/100))*((D35+F35*'⚙️ Calibrage'!$B$9)/MAX(0.01,1-J35/100))/'⚙️ Calibrage'!$B$10,0) | P35: =IFERROR(VLOOKUP(O35,'⚙️ Calibrage'!$D$2:$E$29,2,TRUE),"?") | R35: cerbere.png | S35: Molosse à trois têtes gardant les portes de l'abîme.
A36: dragonnet | B36: Dragonnet | C36: draconique | D36: 515 | E36: 119 | F36: 28 | G36: 14 | H36: 20 | I36: 150 | J36: 0 | K36: 0 | L36: 438 | M36: 210 | N36: 30 | O36: =ROUND((E36*(1+(H36/100)*MAX(0,I36-100)/100)*(1+G36/100))*((D36+F36*'⚙️ Calibrage'!$B$9)/MAX(0.01,1-J36/100))/'⚙️ Calibrage'!$B$10,0) | P36: =IFERROR(VLOOKUP(O36,'⚙️ Calibrage'!$D$2:$E$29,2,TRUE),"?") | S36: Un jeune dragon, vif et capricieux.
A37: drake_de_braise | B37: Drake de braise | C37: draconique | D37: 704 | E37: 204 | F37: 18 | G37: 8 | H37: 0 | I37: 100 | J37: 0 | K37: 0 | L37: 450 | M37: 216 | N37: 25 | O37: =ROUND((E37*(1+(H37/100)*MAX(0,I37-100)/100)*(1+G37/100))*((D37+F37*'⚙️ Calibrage'!$B$9)/MAX(0.01,1-J37/100))/'⚙️ Calibrage'!$B$10,0) | P37: =IFERROR(VLOOKUP(O37,'⚙️ Calibrage'!$D$2:$E$29,2,TRUE),"?") | S37: Ses morsures laissent des brûlures qui couvent longtemps.
A38: wyverne | B38: Wyverne | C38: draconique | D38: 541 | E38: 126 | F38: 30 | G38: 14 | H38: 20 | I38: 150 | J38: 0 | K38: 0 | L38: 462 | M38: 222 | N38: 20 | O38: =ROUND((E38*(1+(H38/100)*MAX(0,I38-100)/100)*(1+G38/100))*((D38+F38*'⚙️ Calibrage'!$B$9)/MAX(0.01,1-J38/100))/'⚙️ Calibrage'!$B$10,0) | P38: =IFERROR(VLOOKUP(O38,'⚙️ Calibrage'!$D$2:$E$29,2,TRUE),"?") | S38: Elle fond sur sa proie et frappe deux fois avant qu'on la voie.
A39: dragon_de_givre | B39: Dragon de givre | C39: draconique | D39: 822 | E39: 100 | F39: 50 | G39: 8 | H39: 0 | I39: 100 | J39: 0 | K39: 0 | L39: 475 | M39: 228 | N39: 15 | O39: =ROUND((E39*(1+(H39/100)*MAX(0,I39-100)/100)*(1+G39/100))*((D39+F39*'⚙️ Calibrage'!$B$9)/MAX(0.01,1-J39/100))/'⚙️ Calibrage'!$B$10,0) | P39: =IFERROR(VLOOKUP(O39,'⚙️ Calibrage'!$D$2:$E$29,2,TRUE),"?") | S39: Son souffle fige le sang dans les veines.
A40: succube | B40: Succube | C40: demoniaque | D40: 748 | E40: 220 | F40: 19 | G40: 8 | H40: 0 | I40: 100 | J40: 0 | K40: 0 | L40: 488 | M40: 234 | N40: 12 | O40: =ROUND((E40*(1+(H40/100)*MAX(0,I40-100)/100)*(1+G40/100))*((D40+F40*'⚙️ Calibrage'!$B$9)/MAX(0.01,1-J40/100))/'⚙️ Calibrage'!$B$10,0) | P40: =IFERROR(VLOOKUP(O40,'⚙️ Calibrage'!$D$2:$E$29,2,TRUE),"?") | R40: succube.png | S40: Démone envoûtante qui draine la vie de ses proies.
A41: gardien_draconique | B41: Gardien draconique | C41: draconique | D41: 935 | E41: 146 | F41: 38 | G41: 8 | H41: 0 | I41: 100 | J41: 0 | K41: 0 | L41: 488 | M41: 234 | N41: 10 | O41: =ROUND((E41*(1+(H41/100)*MAX(0,I41-100)/100)*(1+G41/100))*((D41+F41*'⚙️ Calibrage'!$B$9)/MAX(0.01,1-J41/100))/'⚙️ Calibrage'!$B$10,0) | P41: =IFERROR(VLOOKUP(O41,'⚙️ Calibrage'!$D$2:$E$29,2,TRUE),"?") | S41: Une écaille-bouclier le protège avant qu'on puisse l'atteindre.
A42: dragon_ancien | B42: Dragon ancien | C42: draconique | D42: 19906 | E42: 170 | F42: 20 | G42: 8 | H42: 0 | I42: 100 | J42: 0 | K42: 0 | L42: 1500 | M42: 720 | N42: 5 | O42: =ROUND((E42*(1+(H42/100)*MAX(0,I42-100)/100)*(1+G42/100))*((D42+F42*'⚙️ Calibrage'!$B$9)/MAX(0.01,1-J42/100))/'⚙️ Calibrage'!$B$10,0) | P42: =IFERROR(VLOOKUP(O42,'⚙️ Calibrage'!$D$2:$E$29,2,TRUE),"?") | S42: Le maître des cimes. Blessé, il devient un brasier.
...

Sheet 🧪 Consommables
A1: Code | B1: Nom | C1: Rareté | D1: Effet | E1: Valeur | F1: Prix vente | G1: Prix achat | H1: Description
A2: potion_soin | B2: Potion de soin | C2: common | D2: heal_percent | E2: 10 | F2: 5 | G2: 20 | H2: Rend 10% des PV max (sans dépasser le maximum).

Sheet 📦 Ressources
A1: Code | B1: Nom | C1: Rareté | D1: Stackable | E1: Stack max | F1: Prix vente | G1: Prix achat | H1: Description
A2: dent_de_gobelin | B2: Dent de gobelin | C2: common | D2: oui | E2: ∞ | F2: 0 | G2: 0
A3: fragment_d_me | B3: Fragment d'âme | C3: common | D3: oui | E3: ∞ | F3: 0 | G3: 0
A4: gel_e | B4: Gelée | C4: common | D4: oui | E4: ∞ | F4: 0 | G4: 0
A5: c_ur_corrompu | B5: Cœur corrompu | C5: common | D5: oui | E5: ∞ | F5: 0 | G5: 0
A6: croc_primordial | B6: Croc primordial | C6: common | D6: oui | E6: ∞ | F6: 0 | G6: 0 | H6: Un croc ancien, encore tiède de la magie du sanctuaire.
A7: sang_lunaire | B7: Sang lunaire | C7: common | D7: oui | E7: ∞ | F7: 0 | G7: 0 | H7: Une goutte de sang qui luit d'un éclat d'argent sous l'éclipse.
A8: ecaille_de_dragon | B8: Écaille de dragon | C8: common | D8: oui | E8: ∞ | F8: 0 | G8: 0 | H8: Plus dure que l'acier, encore chaude du souffle qui l'a forgée.
A9: eclat_du_neant | B9: Éclat du néant | C9: common | D9: oui | E9: ∞ | F9: 0 | G9: 0 | H9: Un fragment de vide solidifié. Il semble aspirer la lumière.

Sheet 🏪 Shop
A1: Code item | B1: Nom | C1: Catégorie | D1: Prix achat | E1: Prix vente max | F1: Prix vente min | G1: Seuil stock | H1: Activé
A2: potion_soin | B2: Potion de soin | C2: consumable | D2: 20 | E2: 5 | F2: 2 | G2: 100 | H2: oui

Sheet 🌳 Skill Tree
A1: Code | B1: Nom | C1: Type | D1: Forme | E1: Départ | F1: Niveau max | G1: Coûts/niveau | H1: Effets | I1: Prérequis | J1: Règle | K1: Position | L1: Icône | M1: Description
A2: racine_combat | B2: Aventurier | C2: Départ | D2: Départ | E2: oui | F2: 1 | G2: 0 | H2: — | I2: départ | K2: -80, 450 | L2: ⭐ | M2: Le commencement. Les trois voies de combat partent d'ici.
A3: voie_attaque | B3: Voie du Guerrier | C3: Attaque | D3: Voies | F3: 1 | G3: 1 | H3: atk_percent → [5] | I3: Aventurier | K3: -80, 260 | L3: ⚔️
A4: voie_defense | B4: Voie du Protecteur | C4: Défense | D4: Voies | F4: 1 | G4: 1 | H4: def_percent → [5] | I4: Aventurier | K4: 85, 545 | L4: 🛡️
A5: voie_support | B5: Voie du Support | C5: Support | D5: Voies | F5: 1 | G5: 1 | H5: hp_max_percent → [5] | I5: Aventurier | K5: -245, 545 | L5: ❤️
A6: classe_combattant | B6: Combattant | C6: Classe | D6: Classes | F6: 1 | G6: 2 | H6: grant_class → [combattant] hp_max_percent → [5] atk_percent → [5] | I6: Attaque, Deg. Crit., Défense, Régénération | J6: toutes | K6: 249, 260 | L6: 👊 | M6: Classe Combattant : +5 % de PV max et +5 % d'attaque.
A7: classe_paladin | B7: Paladin | C7: Classe | D7: Classes | F7: 1 | G7: 2 | H7: grant_class → [paladin] heal_received_percent → [50] def_percent → [5] | I7: PV, Défense, Régénération, Rég. Mana | J7: toutes | K7: -80, 830 | L7: 🏰 | M7: Classe Paladin : soins reçus +50 % et +5 % de défense.
A8: classe_vampire | B8: Vampire | C8: Classe | D8: Classes | F8: 1 | G8: 2 | H8: grant_class → [vampire] lifesteal_percent → [5] | I8: Attaque, Deg. Crit., PV, Rég. Mana | J8: toutes | K8: -409, 260 | L8: 🧛 | M8: Classe Vampire : se soigne de 5 % des dégâts infligés.
A9: racine_explorateur | B9: Explorateur | C9: Départ | D9: Départ | E9: oui | F9: 1 | G9: 0 | H9: — | I9: départ | K9: 1090, -230 | L9: 🧭 | M9: La voie de l'explorateur.
A10: axe_or | B10: Bonus Or | C10: Utilité | D10: Passives | F10: 3 | G10: 1,2,3 | H10: gold_drop_percent → [1,4,10] | I10: Explorateur | K10: 1224, -96 | L10: 💰
A11: axe_drop | B11: Chance Drop | C11: Utilité | D11: Passives | F11: 3 | G11: 1,2,3 | H11: drop_rate_multiplier → [10,40,100] | I11: Bonus Or, Bonus XP | J11: toutes | K11: 1090, 55 | L11: 🍀
A12: axe_xp | B12: Bonus XP | C12: Utilité | D12: Passives | F12: 3 | G12: 1,2,3 | H12: xp_drop_percent → [1,4,10] | I12: Explorateur | K12: 956, -96 | L12: ⚡
A13: axe_confort | B13: Confort | C13: Utilité | D13: Passives | F13: 1 | G13: 1 | H13: unlock_feature → [notify_cooldowns] | I13: Chance Drop | K13: 1090, 245 | L13: 🎁 | M13: Reçois un message privé quand un de tes temps de recharge est terminé.
A14: passif_1 | B14: PV | C14: Support | D14: Stats | F14: 1 | G14: 3 | H14: hp_max_percent → [1] | I14: Voie du Support | K14: -409, 640 | L14: ❤️
A15: passif_4 | B15: Vitesse | C15: Support | D15: Stats Avancées | F15: 1 | G15: 3 | H15: speed_flat → [0.5] | I15: PV | K15: -416, 786 | L15: 💨
A16: passif_5 | B16: Vitesse | C16: Support | D16: Stats Avancées | F16: 1 | G16: 3 | H16: speed_flat → [0.5] | I16: PV | K16: -539, 573 | L16: 💨
A17: passif_6 | B17: PV | C17: Support | D17: Stats | F17: 1 | G17: 3 | H17: hp_max_percent → [1] | I17: Vitesse | K17: -650, 450 | L17: ❤️
A18: passif_7 | B18: PV | C18: Support | D18: Stats | F18: 1 | G18: 3 | H18: hp_max_percent → [1] | I18: Vitesse | K18: -366, 943 | L18: ❤️
A19: passif_8 | B19: PV | C19: Support | D19: Stats | F19: 1 | G19: 3 | H19: hp_max_percent → [1] | I19: Voie du Support | K19: -222, 697 | L19: ❤️
A20: passif_9 | B20: PV | C20: Support | D20: Stats | F20: 1 | G20: 3 | H20: hp_max_percent → [1] | I20: Voie du Support | K20: -365, 450 | L20: ❤️
A21: stat_1 | B21: Défense | C21: Défense | D21: Stats | F21: 1 | G21: 3 | H21: def_percent → [1] | I21: Voie du Protecteur | K21: 249, 640 | L21: 🛡️
A22: actif_1 | B22: Attaque | C22: Attaque | D22: Stats | F22: 1 | G22: 3 | H22: atk_percent → [1] | I22: Voie du Guerrier | K22: -80, 70 | L22: ⚔️
A23: actif_2 | B23: Attaque | C23: Attaque | D23: Stats | F23: 1 | G23: 3 | H23: atk_percent → [1] | I23: Voie du Guerrier | K23: -222, 203 | L23: ⚔️
A24: actif_3 | B24: Attaque | C24: Attaque | D24: Stats | F24: 1 | G24: 3 | H24: atk_percent → [1] | I24: Voie du Guerrier | K24: 63, 203 | L24: ⚔️
A25: actif_6 | B25: Vitesse | C25: Attaque | D25: Stats Avancées | F25: 1 | G25: 3 | H25: speed_flat → [0.5] | I25: Attaque | K25: -203, -9 | L25: 💨
... A40: passif_10 | B40: Rég. Mana | C40: Support | D40: Stats Avancées | F40: 1 | G40: 3 | H40: mana_regeneration_flat → [1] | I40: PV | K40: -539, 327 | L40: 🔷
A41: passif_14 | B41: AOE | C41: Mage | D41: Passives | F41: 1 | G41: 3 | H41: splash_damage_percent → [25] | I41: Rég. Mana, Deg. Crit. | J41: toutes | K41: -574, 165 | L41: 🔮 | M41: Les attaques infligent aussi des dégats aux ennemis adjacents la cible, 25% de dégats de l'attaque.
A42: type_1_6 | B42: Mage | C42: Classe | D42: Classes | F42: 1 | G42: 2 | H42: grant_class → [mage] mage_affinity_bonus → [1] | I42: Deg. Crit., Rég. Mana | J42: toutes | K42: -820, 22 | L42: 🧙 | M42: Classe Mage : quand ton coup s'infuse d'un élément (le monstre y est faible), le bonus élémentaire est multiplié par 1,25 si ton affinité dans cet élément atteint 25, par 1,5 à 50, par 2 à 100.
A43: type_1_8 | B43: Chance Crit. | C43: Mage | D43: Stats Avancées | F43: 1 | G43: 3 | H43: crit_chance_flat → [1] | I43: AOE | K43: -550, -20 | L43: 🎯
A44: type_1_10 | B44: Mana | C44: Mage | D44: Stats Avancées | F44: 1 | G44: 3 | H44: mana_max_flat → [5] | I44: AOE | K44: -722, 278 | L44: 💧
A45: type_1_1 | B45: Rég. Mana | C45: Mage | D45: Stats Avancées | F45: 1 | G45: 3 | H45: mana_regeneration_flat → [1] | I45: Mana | K45: -906, 229 | L45: 🔷
A46: type_1_2 | B46: Deg. Crit. | C46: Mage | D46: Stats Avancées | F46: 1 | G46: 3 | H46: crit_damage_flat → [5] | I46: Chance Crit. | K46: -685, -155 | L46: 💥
A47: passif_11 | B47: Résistant | C47: Gardien | D47: Passives | F47: 1 | G47: 3 | H47: damage_taken_reduction_percent → [10] | I47: Rég. Mana, Régénération | J47: toutes | K47: -80, 1020 | L47: 🫧 | M47: Réduit de 10% les dégats reçus.
A48: type_1_3 | B48: Egide | C48: Classe | D48: Classes | F48: 1 | G48: 2 | H48: grant_class → [egide] team_shield_percent → [10] | I48: Rég. Mana, Régénération | J48: toutes | K48: -80, 1305 | L48: 🗿 | M48: Au début du combat donne un bouclier de 10% de ses points de vie max à lui et tous ses alliés.
A49: type_1_4 | B49: Mana | C49: Gardien | D49: Stats Avancées | F49: 1 | G49: 3 | H49: mana_max_flat → [5] | I49: Résistant | K49: -252, 1092 | L49: 💧
A50: type_1_5 | B50: Esquive | C50: Gardien | D50: Stats Avancées | F50: 1 | G50: 3 | H50: dodge_flat → [1] | I50: Résistant | K50: 92, 1092 | L50: 🌀
A51: type_1_7 | B51: Régénération | C51: Gardien | D51: Stats Avancées | F51: 1 | G51: 3 | H51: hp_regeneration_flat → [5] | I51: Esquive | K51: 141, 1276 | L51: ✨
A52: type_1_9 | B52: Rég. Mana | C52: Gardien | D52: Stats Avancées | F52: 1 | G52: 3 | H52: mana_regeneration_flat → [1] | I52: Mana | K52: -301, 1276 | L52: 🔷
A53: passif_12 | B53: Tenace | C53: Sentinelle | D53: Passives | F53: 1 | G53: 3 | H53: last_stand → [1] | I53: Deg. Crit., Régénération | J53: toutes | K53: 414, 165 | L53: 💀 | M53: Lors d'un combat, la première attaque devant le tuer le laisse à 1 pv à la place.
A54: type_1_11 | B54: Titan | C54: Classe | D54: Classes | F54: 1 | G54: 2 | H54: grant_class → [titan] damage_dealt_percent → [5] damage_taken_reduction_percent → [5] | I54: Deg. Crit., Régénération | J54: toutes | K54: 660, 23 | L54: 🦾 | M54: Inflige 5% de dégats supplémentaires et réduit de 5% les dégats reçus.
...

Sheet 🏷️ Titres
A1: Code | B1: Nom | C1: Icône | D1: Exclusif | E1: Condition | F1: Cible / Valeur | G1: Effets | H1: Description
A2: slime_slayer | B2: Slime Slayer | C2: 🟢 | D2: non | E2: kills_family | F2: slime / 100 | G2: damage_bonus_vs_family → target=slime, value=10 damage_reduction_from_family → target=slime, value=10 | H2: Tueur de slimes confirmé. +10% dégâts infligés et -10% dégâts subis face aux slimes.
A3: gobelin_slayer | B3: Gobelin Slayer | C3: 👹 | D3: non | E3: kills_family | F3: gobelin / 100 | G3: damage_bonus_vs_family → target=gobelin, value=10 damage_reduction_from_family → target=gobelin, value=10 | H3: Bourreau des gobelins. +10% dégâts infligés et -10% dégâts subis face aux gobelins.
A4: fleau_semaine | B4: Fléau de la semaine | C4: ⚔️ | D4: oui | E4: weekly_role_trial | F4: dps | G4: damage_dealt_pct → value=2 | H4: Meilleur score DPS de la semaine aux défis (/defi). +2 % de dégâts infligés. Remis en jeu chaque dimanche à 20 h.
A5: bastion_semaine | B5: Bastion de la semaine | C5: 🛡️ | D5: oui | E5: weekly_role_trial | F5: tank | G5: damage_taken_reduction_pct → value=2 | H5: Meilleur score Tank de la semaine aux défis (/defi). −2 % de dégâts reçus. Remis en jeu chaque dimanche à 20 h.
A6: ange_gardien_semaine | B6: Ange gardien de la semaine | C6: 💚 | D6: oui | E6: weekly_role_trial | F6: soutien | G6: heal_power_pct → value=2 | H6: Meilleur score Soutien de la semaine aux défis (/defi). +2 % de soins donnés. Remis en jeu chaque dimanche à 20 h.
A7: champion_semaine | B7: Champion de la semaine | C7: 👑 | D7: oui | E7: weekly_role_trial | F7: general | G7: champion_all_stats → value=1 | H7: Meilleur classement général de la semaine aux défis (/defi). +1 % sur toutes vos stats (multiplicatif sur PV/atk/def, additif sur crit/esquive, +1 flat sur vitesse/régen). Remis en jeu chaque dimanche à 20 h.
A8: farmer_fou | B8: Le Farmer Fou | C8: 🌾 | D8: oui | E8: kills_record | F8: — | G8: gold_xp_bonus_pct → value=1 | H8: Détenteur du record absolu de monstres tués. +1% sur l'or et l'XP gagnés à la fin d'un combat (uniquement pour le détenteur). Perdu dès qu'un autre joueur dépasse votre record.
A9: bourreau | B9: Le Bourreau | C9: 🩸 | D9: non | E9: kills_total | F9: 500 | G9: crit_damage_flat → value=5 | H9: Tueur impitoyable de 500 monstres au total. +5% sur les dégâts critiques (additif sur crit_damage).
A10: intouchable | B10: L'Intouchable | C10: 🌪️ | D10: non | E10: dodges_total | F10: 100 | G10: dodge_flat → value=1 | H10: Esquiveur aguerri (100 esquives encaissées en combat de groupe). +1% d'esquive permanent.
A11: habitue_taverne | B11: Habitué de la taverne | C11: 🍻 | D11: non | E11: daily_streak | F11: 7 | G11: gold_xp_bonus_pct → value=1 | H11: Série /daily de 7 jours. +1 % sur l'or et l'XP gagnés en combat.
A12: taverne_addict | B12: Taverne Addict | C12: 🍺 | D12: non | E12: daily_streak | F12: 30 | G12: crit_damage_flat → value=3 | H12: Série /daily de 30 jours. +3 % de dégâts critiques.
... A29: ma_survie_avant_tout | B29: Ma survie avant tout | C29: 🛡️ | D29: non | E29: event | F29: — | G29: dodge_flat → value=1 speed_flat → value=1 defense_flat → value=10 hp_max_flat → value=200 | H29: A ignoré une « petite fille » qui s'est révélée être un monstre déguisé — l'instinct de survie récompensé. Esquive +1%, Vitesse +1, Défense +10, PV max +200.

Sheet 🐉 World Bosses
A1: Code | B1: Nom | C1: Famille | D1: PV max | E1: Atk | F1: Def | G1: Vit | H1: Crit % | I1: Crit dmg | J1: Esquive | K1: Modifiers | L1: Poids spawn | M1: Lore
A2: slime_titan | B2: Titan Visqueux | D2: 13000 | E2: 110 | F2: 9 | G2: 8 | H2: 0 | I2: 100 | J2: 0 | K2: damage_immunity_threshold = 5 auto_heal_per_turn = 32 | L2: 100 | M2: Un slime ancestral devenu colosse, sa masse étouffante absorbe les coups les plus faibles et se régénère lentement.
A3: gobelin_warlord | B3: Seigneur de Guerre Gobelin | D3: 16000 | E3: 212 | F3: 16 | G3: 12 | H3: 5 | I3: 130 | J3: 5 | K3: enrage_below_pct = 30 enrage_attack_multiplier = 1.5 adds = {'attack': 148, 'summon_turn_interval': 4, 'max_active': 3} | L3: 8 | M3: Le chef d'une horde sanguinaire. Plus il est blessé, plus sa rage l'amplifie, et il appelle des renforts.
A4: stone_colossus | B4: Colosse de Pierre | D4: 209000 | E4: 350 | F4: 23 | G4: 5 | H4: 0 | I4: 100 | J4: 0 | K4: damage_immunity_threshold = 27 reflect_pct = 15 | L4: 3 | M4: Une statue runique animée par d'antiques magies. Inébranlable face aux frappes faibles, sa carapace renvoie une part des coups.
A5: shadow_wraith | B5: Spectre des Ténèbres | D5: 186000 | E5: 473 | F5: 30 | G5: 18 | H5: 10 | I5: 150 | J5: 30 | K5: crit_immunity = True phases = [{'below_pct': 50, 'attack_multiplier': 1.3}, {'below_pct': 20, 'attack_multiplier': 1.6}] | L5: 2 | M5: Une entité incorporelle qui glisse entre les coups. Les coups critiques traversent sa forme étherée, et il mute en s'affaiblissant.
A6: ancient_dragon | B6: Dragon Ancestral | D6: 111000 | E6: 585 | F6: 37 | G6: 15 | H6: 25 | I6: 200 | J6: 10 | K6: damage_immunity_threshold = 43 enrage_below_pct = 25 enrage_attack_multiplier = 1.8 auto_heal_per_turn = 179 reflect_pct = 20 adds = {'attack': 351, 'summon_turn_interval': 5, 'max_active': 2} phases = [{'below_pct': 50, 'attack_multiplier': 1.25}] | L6: 1 | M6: Le sommet de l'évolution. Inflige des coups dévastateurs, renvoie les frappes, invoque des drakelings, se régénère et entre en rage à la fin.

Sheet ⚙️ Calibrage
A1: ⚙️ Calibrage du score de puissance — NE PAS supprimer (formules liées) | D1: Score ≥ | E1: Rang
A2: Base ATK | B2: 10 | D2: 0 | E2: F-
A3: Base DEF | B3: 5 | D3: 206 | E3: F
A4: Base PV | B4: 100 | D4: 383 | E4: F+
A5: Base Crit % | B5: 5 | D5: 686 | E5: E-
A6: Base Crit dmg (100 = neutre) | B6: 150 | D6: 966 | E6: E
A7: Base Esquive % | B7: 0 | D7: 1352 | E7: E+
A8: Base Vitesse | B8: 5 | D8: 2259 | E8: D-
A9: K_DEF (1 DEF = N PV effectifs) | B9: 25 | D9: 2998 | E9: D
A10: SCALE (diviseur) | B10: 42 | D10: 3992 | E10: D+
A11: Power base (auto) | B11: =$B$2*(1+($B$5/100)*MAX(0,$B$6-100)/100)*(1+$B$8/100)*(($B$4+$B$3*$B$9)/MAX(0.01,1-$B$7/100))/$B$10 | D11: 4886 | E11: C-
D12: 7610 | E12: C
D13: 8898 | E13: C+
D14: 10460 | E14: B-
D15: 14968 | E15: B
D16: 16978 | E16: B+
D17: 19589 | E17: A-
D18: 22354 | E18: A
D19: 24996 | E19: A+
D20: 28086 | E20: S-
D21: 30905 | E21: S
D22: 42500 | E22: S+
D23: 68100 | E23: SS-
... D29: 4404700 | E29: Ω
